Workbook

Sheet Données
A1: PRET | B1: Intercept | C1: TX_ENDET (X1) | D1: ANTEC (X2) | E1: PRIX(X3) | F1: REVENU(X4) | G1: MARIAGE (X5) | H1: EMP (X6) | I1: TAUX (X7) | J1: TX_EFF | K1: SEXE | L1: Y Pred | M1: Résidu | Q1: Avec LN:
A2: 128000 | B2: 1 | C2: 34.099998 | D2: 0 | E2: 160000 | F2: 4583 | G2: 1 | H2: 0 | I2: 1 | J2: 22.540001 | K2: 1 | L2: =Résultats!G$32+Résultats!G$33*Données!C2+Résultats!G$34*Données!D2+Résultats!G$35*Données!E2+Résultats!G$36*Données!F2+Résultats!G$37*Données!G2+Résultats!G$38*Données!H2+Résultats!G$39*Données!I2 -> 136266.74 | M2: =A2-L2 -> -8266.742 | Q2: PRET | R2: Intercept | S2: TX_ENDET (X1) | T2: ANTEC (X2) | U2: Ln prix(X3) | V2: Ln revenue(X4) | W2: MARIAGE (X5) | X2: EMP (X6) | Y2: TAUX (X7) | Z2: Y pred | AA2: Résidu
A3: 128000 | B3: 1 | C3: 26 | D3: 0 | E3: 143000 | F3: 2666 | G3: 0 | H3: 1 | I3: 0 | J3: 19 | K3: 1 | L3: =Résultats!G$32+Résultats!G$33*Données!C3+Résultats!G$34*Données!D3+Résultats!G$35*Données!E3+Résultats!G$36*Données!F3+Résultats!G$37*Données!G3+Résultats!G$38*Données!H3+Résultats!G$39*Données!I3 -> 96742.218 | M3: =A3-L3 -> 31257.782 | Q3: 128000 | R3: 1 | S3: 34.099998 | T3: 0 | U3: =LN(E2) -> 11.982929 | V3: =LN(F2) -> 8.4301091 | W3: 1 | X3: 0 | Y3: 1 | Z3: ='Résultat (Ln)'!F$30+'Résultat (Ln)'!F$31*Données!S3+'Résultat (Ln)'!F$32*Données!T3+'Résultat (Ln)'!F$33*Données!U3+'Résultat (Ln)'!F$34*Données!V3+'Résultat (Ln)'!F$35*Données!W3+'Résultat (Ln)'!F$36*Données!X3+'Résultat (Ln)'!F$37*Données!Y3 -> 151388.5 | AA3: =Q3-Z3 -> -23388.496
A4: 66000 | B4: 1 | C4: 37 | D4: 1 | E4: 110000 | F4: 3000 | G4: 1 | H4: 0 | I4: 0 | J4: 24 | K4: 1 | L4: =Résultats!G$32+Résultats!G$33*Données!C4+Résultats!G$34*Données!D4+Résultats!G$35*Données!E4+Résultats!G$36*Données!F4+Résultats!G$37*Données!G4+Résultats!G$38*Données!H4+Résultats!G$39*Données!I4 -> 108105.5 | M4: =A4-L4 -> -42105.499 | Q4: 128000 | R4: 1 | S4: 26 | T4: 0 | U4: =LN(E3) -> 11.8706 | V4: =LN(F3) -> 7.8883345 | W4: 0 | X4: 1 | Y4: 0 | Z4: ='Résultat (Ln)'!F$30+'Résultat (Ln)'!F$31*Données!S4+'Résultat (Ln)'!F$32*Données!T4+'Résultat (Ln)'!F$33*Données!U4+'Résultat (Ln)'!F$34*Données!V4+'Résultat (Ln)'!F$35*Données!W4+'Résultat (Ln)'!F$36*Données!X4+'Résultat (Ln)'!F$37*Données!Y4 -> 95475.776 | AA4: =Q4-Z4 -> 32524.224
A5: 120000 | B5: 1 | C5: 32.099998 | D5: 0 | E5: 134000 | F5: 2583 | G5: 1 | H5: 0 | I5: 0 | J5: 25.1 | K5: 1 | L5: =Résultats!G$32+Résultats!G$33*Données!C5+Résultats!G$34*Données!D5+Résultats!G$35*Données!E5+Résultats!G$36*Données!F5+Résultats!G$37*Données!G5+Résultats!G$38*Données!H5+Résultats!G$39*Données!I5 -> 108027.58 | M5: =A5-L5 -> 11972.415 | Q5: 66000 | R5: 1 | S5: 37 | T5: 1 | U5: =LN(E4) -> 11.608236 | V5: =LN(F4) -> 8.0063676 | W5: 1 | X5: 0 | Y5: 0 | Z5: ='Résultat (Ln)'!F$30+'Résultat (Ln)'!F$31*Données!S5+'Résultat (Ln)'!F$32*Données!T5+'Résultat (Ln)'!F$33*Données!U5+'Résultat (Ln)'!F$34*Données!V5+'Résultat (Ln)'!F$35*Données!W5+'Résultat (Ln)'!F$36*Données!X5+'Résultat (Ln)'!F$37*Données!Y5 -> 93144.654 | AA5: =Q5-Z5 -> -27144.654
A6: 111000 | B6: 1 | C6: 33 | D6: 0 | E6: 138000 | F6: 2208 | G6: 0 | H6: 0 | I6: 0 | J6: 21 | K6: 1 | L6: =Résultats!G$32+Résultats!G$33*Données!C6+Résultats!G$34*Données!D6+Résultats!G$35*Données!E6+Résultats!G$36*Données!F6+Résultats!G$37*Données!G6+Résultats!G$38*Données!H6+Résultats!G$39*Données!I6 -> 103185.91 | M6: =A6-L6 -> 7814.0859 | Q6: 120000 | R6: 1 | S6: 32.099998 | T6: 0 | U6: =LN(E5) -> 11.805595 | V6: =LN(F5) -> 7.8567068 | W6: 1 | X6: 0 | Y6: 0 | Z6: ='Résultat (Ln)'!F$30+'Résultat (Ln)'!F$31*Données!S6+'Résultat (Ln)'!F$32*Données!T6+'Résultat (Ln)'!F$33*Données!U6+'Résultat (Ln)'!F$34*Données!V6+'Résultat (Ln)'!F$35*Données!W6+'Résultat (Ln)'!F$36*Données!X6+'Résultat (Ln)'!F$37*Données!Y6 -> 99766.541 | AA6: =Q6-Z6 -> 20233.459
A7: 141000 | B7: 1 | C7: 36 | D7: 0 | E7: 157000 | F7: 6000 | G7: 0 | H7: 0 | I7: 0 | J7: 32 | K7: 1 | L7: =Résultats!G$32+Résultats!G$33*Données!C7+Résultats!G$34*Données!D7+Résultats!G$35*Données!E7+Résultats!G$36*Données!F7+Résultats!G$37*Données!G7+Résultats!G$38*Données!H7+Résultats!G$39*Données!I7 -> 122852.13 | M7: =A7-L7 -> 18147.873 | Q7: 111000 | R7: 1 | S7: 33 | T7: 0 | U7: =LN(E6) -> 11.835009 | V7: =LN(F6) -> 7.6998424 | W7: 0 | X7: 0 | Y7: 0 | Z7: ='Résultat (Ln)'!F$30+'Résultat (Ln)'!F$31*Données!S7+'Résultat (Ln)'!F$32*Données!T7+'Résultat (Ln)'!F$33*Données!U7+'Résultat (Ln)'!F$34*Données!V7+'Résultat (Ln)'!F$35*Données!W7+'Résultat (Ln)'!F$36*Données!X7+'Résultat (Ln)'!F$37*Données!Y7 -> 95106.001 | AA7: =Q7-Z7 -> 15893.999
A8: 276000 | B8: 1 | C8: 37 | D8: 0 | E8: 346000 | F8: 7500 | G8: 0 | H8: 0 | I8: 1 | J8: 36 | K8: 1 | L8: =Résultats!G$32+Résultats!G$33*Données!C8+Résultats!G$34*Données!D8+Résultats!G$35*Données!E8+Résultats!G$36*Données!F8+Résultats!G$37*Données!G8+Résultats!G$38*Données!H8+Résultats!G$39*Données!I8 -> 225087.1 | M8: =A8-L8 -> 50912.897 | Q8: 141000 | R8: 1 | S8: 36 | T8: 0 | U8: =LN(E7) -> 11.964001 | V8: =LN(F7) -> 8.6995147 | W8: 0 | X8: 0 | Y8: 0 | Z8: ='Résultat (Ln)'!F$30+'Résultat (Ln)'!F$31*Données!S8+'Résultat (Ln)'!F$32*Données!T8+'Résultat (Ln)'!F$33*Données!U8+'Résultat (Ln)'!F$34*Données!V8+'Résultat (Ln)'!F$35*Données!W8+'Résultat (Ln)'!F$36*Données!X8+'Résultat (Ln)'!F$37*Données!Y8 -> 140636.11 | AA8: =Q8-Z8 -> 363.88974
A9: 100000 | B9: 1 | C9: 30.700001 | D9: 0 | E9: 99699.997 | F9: 3234 | G9: 1 | H9: 1 | I9: 0 | J9: 19.309999 | K9: 1 | L9: =Résultats!G$32+Résultats!G$33*Données!C9+Résultats!G$34*Données!D9+Résultats!G$35*Données!E9+Résultats!G$36*Données!F9+Résultats!G$37*Données!G9+Résultats!G$38*Données!H9+Résultats!G$39*Données!I9 -> 90039.173 | M9: =A9-L9 -> 9960.8267 | Q9: 276000 | R9: 1 | S9: 37 | T9: 0 | U9: =LN(E8) -> 12.754194 | V9: =LN(F8) -> 8.9226583 | W9: 0 | X9: 0 | Y9: 1 | Z9: ='Résultat (Ln)'!F$30+'Résultat (Ln)'!F$31*Données!S9+'Résultat (Ln)'!F$32*Données!T9+'Résultat (Ln)'!F$33*Données!U9+'Résultat (Ln)'!F$34*Données!V9+'Résultat (Ln)'!F$35*Données!W9+'Résultat (Ln)'!F$36*Données!X9+'Résultat (Ln)'!F$37*Données!Y9 -> 246908.5 | AA9: =Q9-Z9 -> 29091.497
A10: 267000 | B10: 1 | C10: 49 | D10: 0 | E10: 422000 | F10: 5417 | G10: 1 | H10: 0 | I10: 0 | J10: 26.51 | K10: 1 | L10: =Résultats!G$32+Résultats!G$33*Données!C10+Résultats!G$34*Données!D10+Résultats!G$35*Données!E10+Résultats!G$36*Données!F10+Résultats!G$37*Données!G10+Résultats!G$38*Données!H10+Résultats!G$39*Données!I10 -> 267414.35 | M10: =A10-L10 -> -414.34659 | Q10: 100000 | R10: 1 | S10: 30.700001 | T10: 0 | U10: =LN(E9) -> 11.509921 | V10: =LN(F9) -> 8.081475 | W10: 1 | X10: 1 | Y10: 0 | Z10: ='Résultat (Ln)'!F$30+'Résultat (Ln)'!F$31*Données!S10+'Résultat (Ln)'!F$32*Données!T10+'Résultat (Ln)'!F$33*Données!U10+'Résultat (Ln)'!F$34*Données!V10+'Résultat (Ln)'!F$35*Données!W10+'Résultat (Ln)'!F$36*Données!X10+'Résultat (Ln)'!F$37*Données!Y10 -> 72486.992 | AA10: =Q10-Z10 -> 27513.008
A11: 175000 | B11: 1 | C11: 37 | D11: 0 | E11: 346700.01 | F11: 6292 | G11: 1 | H11: 0 | I11: 0 | J11: 26 | K11: 1 | L11: =Résultats!G$32+Résultats!G$33*Données!C11+Résultats!G$34*Données!D11+Résultats!G$35*Données!E11+Résultats!G$36*Données!F11+Résultats!G$37*Données!G11+Résultats!G$38*Données!H11+Résultats!G$39*Données!I11 -> 220164.29 | M11: =A11-L11 -> -45164.291 | Q11: 267000 | R11: 1 | S11: 49 | T11: 0 | U11: =LN(E10) -> 12.952761 | V11: =LN(F10) -> 8.5972974 | W11: 1 | X11: 0 | Y11: 0 | Z11: ='Résultat (Ln)'!F$30+'Résultat (Ln)'!F$31*Données!S11+'Résultat (Ln)'!F$32*Données!T11+'Résultat (Ln)'!F$33*Données!U11+'Résultat (Ln)'!F$34*Données!V11+'Résultat (Ln)'!F$35*Données!W11+'Résultat (Ln)'!F$36*Données!X11+'Résultat (Ln)'!F$37*Données!Y11 -> 264160.54 | AA11: =Q11-Z11 -> 2839.4563
A12: 95000 | B12: 1 | C12: 37.099998 | D12: 0 | E12: 135000 | F12: 2333 | G12: 1 | H12: 0 | I12: 0 | J12: 26.1 | K12: 1 | L12: =Résultats!G$32+Résultats!G$33*Données!C12+Résultats!G$34*Données!D12+Résultats!G$35*Données!E12+Résultats!G$36*Données!F12+Résultats!G$37*Données!G12+Résultats!G$38*Données!H12+Résultats!G$39*Données!I12 -> 113753.44 | M12: =A12-L12 -> -18753.443 | Q12: 175000 | R12: 1 | S12: 37 | T12: 0 | U12: =LN(E11) -> 12.756215 | V12: =LN(F11) -> 8.7470343 | W12: 1 | X12: 0 | Y12: 0 | Z12: ='Résultat (Ln)'!F$30+'Résultat (Ln)'!F$31*Données!S12+'Résultat (Ln)'!F$32*Données!T12+'Résultat (Ln)'!F$33*Données!U12+'Résultat (Ln)'!F$34*Données!V12+'Résultat (Ln)'!F$35*Données!W12+'Résultat (Ln)'!F$36*Données!X12+'Résultat (Ln)'!F$37*Données!Y12 -> 232626.74 | AA12: =Q12-Z12 -> -57626.742
A13: 158000 | B13: 1 | C13: 42 | D13: 1 | E13: 210000 | F13: 3036 | G13: 1 | H13: 0 | I13: 1 | J13: 29 | K13: 1 | L13: =Résultats!G$32+Résultats!G$33*Données!C13+Résultats!G$34*Données!D13+Résultats!G$35*Données!E13+Résultats!G$36*Données!F13+Résultats!G$37*Données!G13+Résultats!G$38*Données!H13+Résultats!G$39*Données!I13 -> 170539.39 | M13: =A13-L13 -> -12539.395 | Q13: 95000 | R13: 1 | S13: 37.099998 | T13: 0 | U13: =LN(E12) -> 11.81303 | V13: =LN(F12) -> 7.7549103 | W13: 1 | X13: 0 | Y13: 0 | Z13: ='Résultat (Ln)'!F$30+'Résultat (Ln)'!F$31*Données!S13+'Résultat (Ln)'!F$32*Données!T13+'Résultat (Ln)'!F$33*Données!U13+'Résultat (Ln)'!F$34*Données!V13+'Résultat (Ln)'!F$35*Données!W13+'Résultat (Ln)'!F$36*Données!X13+'Résultat (Ln)'!F$37*Données!Y13 -> 103818.78 | AA13: =Q13-Z13 -> -8818.7781
A14: 110000 | B14: 1 | C14: 32 | D14: 0 | E14: 143000 | F14: 5720 | G14: 1 | H14: 0 | I14: 0 | J14: 24 | K14: 1 | L14: =Résultats!G$32+Résultats!G$33*Données!C14+Résultats!G$34*Données!D14+Résultats!G$35*Données!E14+Résultats!G$36*Données!F14+Résultats!G$37*Données!G14+Résultats!G$38*Données!H14+Résultats!G$39*Données!I14 -> 118194.14 | M14: =A14-L14 -> -8194.1378 | Q14: 158000 | R14: 1 | S14: 42 | T14: 1 | U14: =LN(E13) -> 12.254863 | V14: =LN(F13) -> 8.0182961 | W14: 1 | X14: 0 | Y14: 1 | Z14: ='Résultat (Ln)'!F$30+'Résultat (Ln)'!F$31*Données!S14+'Résultat (Ln)'!F$32*Données!T14+'Résultat (Ln)'!F$33*Données!U14+'Résultat (Ln)'!F$34*Données!V14+'Résultat (Ln)'!F$35*Données!W14+'Résultat (Ln)'!F$36*Données!X14+'Résultat (Ln)'!F$37*Données!Y14 -> 182991.9 | AA14: =Q14-Z14 -> -24991.901
... A1968: 133000 | B1968: 1 | C1968: 47 | D1968: 0 | E1968: 148000 | F1968: 4583 | G1968: 0 | H1968: 0 | I1968: 0 | J1968: 31 | K1968: 0 | L1968: =Résultats!G$32+Résultats!G$33*Données!C1968+Résultats!G$34*Données!D1968+Résultats!G$35*Données!E1968+Résultats!G$36*Données!F1968+Résultats!G$37*Données!G1968+Résultats!G$38*Données!H1968+Résultats!G$39*Données!I1968 -> 128539.08 | M1968: =A1968-L1968 -> 4460.9229 | Q1968: 98000 | R1968: 1 | S1968: 17 | T1968: 0 | U1968: =LN(E1967) -> 12.278393 | V1968: =LN(F1967) -> 9.1269588 | W1968: 0 | X1968: 0 | Y1968: 0 | Z1968: ='Résultat (Ln)'!F$30+'Résultat (Ln)'!F$31*Données!S1968+'Résultat (Ln)'!F$32*Données!T1968+'Résultat (Ln)'!F$33*Données!U1968+'Résultat (Ln)'!F$34*Données!V1968+'Résultat (Ln)'!F$35*Données!W1968+'Résultat (Ln)'!F$36*Données!X1968+'Résultat (Ln)'!F$37*Données!Y1968 -> 163106.79 | AA1968: =Q1968-Z1968 -> -65106.791
Q1969: 133000 | R1969: 1 | S1969: 47 | T1969: 0 | U1969: =LN(E1968) -> 11.904968 | V1969: =LN(F1968) -> 8.4301091 | W1969: 0 | X1969: 0 | Y1969: 0 | Z1969: ='Résultat (Ln)'!F$30+'Résultat (Ln)'!F$31*Données!S1969+'Résultat (Ln)'!F$32*Données!T1969+'Résultat (Ln)'!F$33*Données!U1969+'Résultat (Ln)'!F$34*Données!V1969+'Résultat (Ln)'!F$35*Données!W1969+'Résultat (Ln)'!F$36*Données!X1969+'Résultat (Ln)'!F$37*Données!Y1969 -> 140194.73 | AA1969: =Q1969-Z1969 -> -7194.7326

Sheet Résultats
A1: Cette feuille est dédiée aux calculs permettant la régression ainsi qu'à vos résultats. Comme expliqué oralement lors des TD, vous devez impérativement rendre ce document avec votre dossier.
A4: k= | B4: 7
A5: Nombre= | B5: 1967 | D5: Minimum X1= | E5: =MIN(Données!C2:C1968) -> 0 | G5: Minimum X2= | H5: =MIN(Données!D2:D1968) -> 0 | J5: Minimum X3= | K5: =MIN(Données!E2:E1968) -> 25000 | M5: Minimum X4= | N5: =MIN(Données!F2:F1968) -> 150 | P5: Minimum X5= | Q5: =MIN(Données!G2:G1968) -> 0 | S5: Minimum X6= | T5: =MIN(Données!H2:H1968) -> 0 | V5: Minimum X7= | W5: =MIN(Données!I2:I1968) -> 0
A6: Min Prêt= | B6: =MIN(Données!A2:A1968) -> 2000 | D6: Maximum X1= | E6: =MAX(Données!C2:C1968) -> 95 | G6: Maximum X2= | H6: =MAX(Données!D2:D1968) -> 1 | J6: Maximum X3= | K6: =MAX(Données!E2:E1968) -> 1535000 | M6: Maximum X4= | N6: =MAX(Données!F2:F1968) -> 81000 | P6: Maximum X5= | Q6: =MAX(Données!G2:G1968) -> 1 | S6: Maximum X6= | T6: =MAX(Données!H3:H1969) -> 9 | V6: Maximum X7= | W6: =MAX(Données!I3:I1969) -> 1
A7: Max Prêt= | B7: =MAX(Données!A2:A1968) -> 980000 | D7: Ecart-type X1 = | E7: =_xlfn.STDEV.S(Données!C2:C1968) -> 8.2746545 | G7: Ecart-type X2 = | H7: =_xlfn.STDEV.S(Données!D2:D1968) -> 0.25202272 | J7: Ecart-type X3 = | K7: =_xlfn.STDEV.S(Données!E2:E1968) -> 128691.94 | M7: Ecart-type X4 = | N7: =_xlfn.STDEV.S(Données!F2:F1968) -> 5289.1044 | P7: Ecart-type X5 = | Q7: =_xlfn.STDEV.S(Données!G2:G1968) -> 0.47369508 | S7: Ecart-type X6 = | T7: =_xlfn.STDEV.S(Données!H2:H1968) -> 0.97221746 | V7: Ecart-type X7 = | W7: =_xlfn.STDEV.S(Données!I2:I1968) -> 0.46265888
A8: Somme= | B8: =SUM(Données!A2:A1968) -> 282106000 | D8: Moyenne X1 = | E8: =AVERAGE(Données!C2:C1968) -> 32.391251 | G8: Moyenne X2 = | H8: =AVERAGE(Données!D2:D1968) -> 0.068124047 | J8: Moyenne X3 = | K8: =AVERAGE(Données!E2:E1968) -> 196669 | M8: Moyenne X4 = | N8: =AVERAGE(Données!F2:F1968) -> 5212.5582 | P8: Moyenne X5 = | Q8: =AVERAGE(Données!G2:G1968) -> 0.66039654 | S8: Moyenne X6 = | T8: =AVERAGE(Données!H2:H1968) -> 0.20132181 | V8: Moyenne X7 = | W8: =AVERAGE(Données!I2:I1968) -> 0.31011693
A9: Moyenne= | B9: =AVERAGE(Données!A2:A1968) -> 143419.42 | D9: Variance X1 = | E9: =_xlfn.VAR.S(Données!C2:C1968) -> 68.469907 | G9: Variance X2 = | H9: =_xlfn.VAR.S(Données!D2:D1968) -> 0.063515452 | J9: Variance X3 = | K9: =_xlfn.VAR.S(Données!E2:E1968) -> 1.6561616e+10 | M9: Variance X4 = | N9: =_xlfn.VAR.S(Données!F2:F1968) -> 27974625 | P9: Variance X5= | Q9: =_xlfn.VAR.S(Données!G2:G1968) -> 0.22438702 | S9: Variance X6= | T9: =_xlfn.VAR.S(Données!H2:H1968) -> 0.9452068 | V9: Variance X7= | W9: =_xlfn.VAR.S(Données!K2:K1968) -> 0.15152509
A10: Variance= | B10: =_xlfn.VAR.S(Données!A2:A1968) -> 6.5385142e+09
A11: Écart types= | B11: =_xlfn.STDEV.S(Données!A2:A1968) -> 80861.08
D15: Y|X | E15: TX_ENDET | F15: ANTEC | G15: PRIX | H15: REVENU | I15: MARIAGE | J15: Emploi | K15: Taux
D16: Prêt | E16: =CORREL(Données!A2:A1968,Données!C2:C1968) -> 0.075501862 | F16: =CORREL(Données!A2:A1968,Données!D2:D1968) -> 0.025403801 | G16: =CORREL(Données!A2:A1968,Données!E2:E1968) -> 0.83454676 | H16: =CORREL(Données!A2:A1968,Données!F2:F1968) -> 0.57513904 | I16: =CORREL(Données!A2:A1968,Données!G2:G1968) -> 0.18279308 | J16: =CORREL(Données!C2:C1968,Données!H2:H1968) -> -0.091137758 | K16: =CORREL(Données!C2:C1968,Données!I2:I1968) -> 0.035810317
D18: X′X | M18: (X′X)^-1 | W18: X'Y
D19: {=MMULT(TRANSPOSE(Données!B2:I1968),Données!B2:I1968)} -> 1967 | E19: 63713.59 | F19: 134 | G19: 3.8684793e+08 | H19: 10253102 | I19: 1299 | J19: 396 | K19: 610 | M19: {=MINVERSE(_xlfn.ANCHORARRAY(D19))} -> 0.01149737 | N19: -0.00027195786 | O19: 0.00023228577 | P19: -1.247544e-09 | Q19: -1.6206942e-07 | R19: -0.0014648179 | S19: -0.00034993965 | T19: -0.0002185946 | W19: {=MMULT(TRANSPOSE(Données!B2:I1968),Données!A2:A1968)} -> 282106000
D20: 63713.59 | E20: 2198374.7 | F20: 4673.9 | G20: 1.2485833e+10 | H20: 3.1174123e+08 | I20: 41845.8 | J20: 11385.5 | K20: 20028.19 | M20: -0.00027195786 | N20: 8.2744104e-06 | O20: -2.2855318e-05 | P20: -1.1215765e-10 | Q20: 4.8388978e-09 | R20: 5.9896794e-06 | S20: 6.1013268e-06 | T20: -9.1985999e-06 | W20: 9.2370848e+09
D21: 134 | E21: 4673.9 | F21: 134 | G21: 26013400 | H21: 736284 | I21: 88 | J21: 24 | K21: 53 | M21: 0.00023228577 | N21: -2.2855318e-05 | O21: 0.0080960016 | P21: 7.3238903e-10 | Q21: -2.273108e-08 | R21: -1.4109539e-05 | S21: 2.9975334e-06 | T21: -0.00019458001 | W21: 20236000
D22: 3.8684793e+08 | E22: 1.2485833e+10 | F22: 26013400 | G22: 1.0864113e+14 | H22: 2.8536113e+12 | I22: 2.7685355e+08 | J22: 72205980 | K22: 1.3417714e+08 | M22: -1.247544e-09 | N22: -1.1215765e-10 | O22: 7.3238903e-10 | P22: 5.3507878e-14 | Q22: -8.3759152e-13 | R22: -1.838151e-09 | S22: 8.9045138e-11 | T22: -4.2173591e-10 | W22: 7.2555104e+13
D23: 10253102 | E23: 3.1174123e+08 | F23: 736284 | G23: 2.8536113e+12 | H23: 108443003534 | I23: 7190875 | J23: 2188004 | K23: 3842568 | M23: -1.6206942e-07 | N23: 4.8388978e-09 | O23: -2.273108e-08 | P23: -8.3759152e-13 | Q23: 3.2964489e-11 | R23: 1.2026451e-08 | S23: -8.8322225e-11 | T23: -2.6265803e-08 | W23: 1954084755000
D24: 1299 | E24: 41845.8 | F24: 88 | G24: 2.7685355e+08 | H24: 7190875 | I24: 1299 | J24: 207 | K24: 408 | M24: -0.0014648179 | N24: 5.9896794e-06 | O24: -1.4109539e-05 | P24: -1.838151e-09 | Q24: 1.2026451e-08 | R24: 0.0023558473 | S24: 6.7231094e-05 | T24: 4.0506029e-06 | W24: 200067000
D25: 396 | E25: 11385.5 | F25: 24 | G25: 72205980 | H25: 2188004 | I25: 207 | J25: 1938 | K25: 165 | M25: -0.00034993965 | N25: 6.1013268e-06 | O25: 2.9975334e-06 | P25: 8.9045138e-11 | Q25: -8.8322225e-11 | R25: 6.7231094e-05 | S25: 0.00054653937 | T25: -6.2478577e-05 | W25: 49730000
D26: 610 | E26: 20028.19 | F26: 53 | G26: 1.3417714e+08 | H26: 3842568 | I26: 408 | J26: 165 | K26: 610 | M26: -0.0002185946 | N26: -9.1985999e-06 | O26: -0.00019458001 | P26: -4.2173591e-10 | Q26: -2.6265803e-08 | R26: 4.0506029e-06 | S26: -6.2478577e-05 | T26: 0.0024492763 | W26: 99915000
D31: (X′X)^-1 * (X′Y) | F31: β
D32: {=MMULT(_xlfn.ANCHORARRAY(M19),_xlfn.ANCHORARRAY(W19))} -> -3438.394 | F32: β0= | G32: =D32 -> -3438.394
D33: 1148.6704 | F33: β1= | G33: =D33 -> 1148.6704
D34: 4848.2487 | F34: β2= | G34: =D34 -> 4848.2487
D35: 0.46695327 | F35: β3= | G35: =D35 -> 0.46695327
D36: 1.9377874 | F36: β4= | G36: =D36 -> 1.9377874
D37: 7016.6185 | F37: β5= | G37: =D37 -> 7016.6185
D38: -1625.2765 | F38: β6= | G38: =D38 -> -1625.2765
D39: 9925.4569 | F39: β7= | G39: =D39 -> 9925.4569
C49: SCT = | D49: =DEVSQ(Données!A2:A1968) -> 1.2854719e+13 | F49: R² = | G49: =1-(D51/D49) -> 0.72036728 | I49: ddl SCE = | J49: =6 -> 6
C50: SCE= | D50: =DEVSQ(Données!L2:L1968) -> 9.260119e+12 | I50: ddl SCR = | J50: =1960 -> 1960
C51: SCR= | D51: =SUMSQ(Données!M2:M1968) -> 3.5946e+12
C54: F observé = | D54: =(D50/B4)/(D51/(B5-B4-1)) -> 720.94543 | F54: p-valeur = | G54: =_xlfn.F.DIST.RT(D54,J49,J50) -> 0
C55: F théorique = | D55: =_xlfn.F.INV.RT(0.05,J49,J50) -> 2.1032022
F56: t théorique = | G56: =_xlfn.T.INV.2T(0.05,J50) -> 1.9611751
D61: =D51/J50 -> 1.8339796e+09
F62: {=D61*_xlfn.ANCHORARRAY(M19)} -> 21085942 | G62: -498765.17 | H62: 426007.36 | I62: -2.2879702 | J62: -297.23201 | K62: -2686446.1 | L62: -641782.19 | M62: -400898.04
F63: -498765.17 | G63: 15175.1 | H63: -41916.186 | I63: -0.20569484 | J63: 8.8744399 | K63: 10984.95 | L63: 11189.709 | M63: -16870.045
F64: 426007.36 | G64: -41916.186 | H64: 14847902 | I64: 1.3431865 | J64: -41.688337 | K64: -25876.606 | L64: 5497.4151 | M64: -356855.77
F65: -2.2879702 | G65: -0.20569484 | H65: 1.3431865 | I65: 9.8132357e-05 | J65: -0.0015361258 | K65: -3.3711314 | L65: 0.16330697 | M65: -0.77345505
...

Sheet Résultat (Ln)
A4: k= | B4: 7
A5: Nombre= | B5: 1967 | D5: Minimum X1= | E5: =MIN(Données!C2:C1968) -> 0 | G5: Minimum X2= | H5: =MIN(Données!D2:D1968) -> 0 | J5: Minimum X3= | K5: =MIN(Données!U2:U1968) -> 10.126631 | M5: Minimum X4= | N5: =MIN(Données!V2:V1968) -> 5.0106353 | P5: Minimum X5= | Q5: =MIN(Données!G2:G1968) -> 0 | S5: Minimum X6= | T5: =MIN(Données!H2:H1968) -> 0 | V5: Minimum X7= | W5: =MIN(Données!I2:I1968) -> 0
A6: Min Prêt= | B6: =MIN(Données!A2:A1968) -> 2000 | D6: Maximum X1= | E6: =MAX(Données!C2:C1968) -> 95 | G6: Maximum X2= | H6: =MAX(Données!D2:D1968) -> 1 | J6: Maximum X3= | K6: =MAX(Données!U2:U1968) -> 14.244041 | M6: Maximum X4= | N6: =MAX(Données!V2:V1968) -> 11.302204 | P6: Maximum X5= | Q6: =MAX(Données!G2:G1968) -> 1 | S6: Maximum X6= | T6: =MAX(Données!H3:H1969) -> 9 | V6: Maximum X7= | W6: =MAX(Données!I3:I1969) -> 1
A7: Max Prêt= | B7: =MAX(Données!A2:A1968) -> 980000 | D7: Ecart-type X1 = | E7: =_xlfn.STDEV.S(Données!C2:C1968) -> 8.2746545 | G7: Ecart-type X2 = | H7: =_xlfn.STDEV.S(Données!D2:D1968) -> 0.25202272 | J7: Ecart-type X3 = | K7: =_xlfn.STDEV.S(Données!U2:U1968) -> 0.49382134 | M7: Ecart-type X4 = | N7: =_xlfn.STDEV.S(Données!V2:V1968) -> 0.59888316 | P7: Ecart-type X5 = | Q7: =_xlfn.STDEV.S(Données!G2:G1968) -> 0.47369508 | S7: Ecart-type X6 = | T7: =_xlfn.STDEV.S(Données!H2:H1968) -> 0.97221746 | V7: Ecart-type X7 = | W7: =_xlfn.STDEV.S(Données!I2:I1968) -> 0.46265888
A8: Somme= | B8: =SUM(Données!A2:A1968) -> 282106000 | D8: Moyenne X1 = | E8: =AVERAGE(Données!C2:C1968) -> 32.391251 | G8: Moyenne X2 = | H8: =AVERAGE(Données!D2:D1968) -> 0.068124047 | J8: Moyenne X3 = | K8: =AVERAGE(Données!E2:E1968) -> 196669 | M8: Moyenne X4 = | N8: =AVERAGE(Données!V2:V1968) -> 8.3379987 | P8: Moyenne X5 = | Q8: =AVERAGE(Données!G2:G1968) -> 0.66039654 | S8: Moyenne X6 = | T8: =AVERAGE(Données!H2:H1968) -> 0.20132181 | V8: Moyenne X7 = | W8: =AVERAGE(Données!I2:I1968) -> 0.31011693
A9: Moyenne= | B9: =AVERAGE(Données!A2:A1968) -> 143419.42 | D9: Variance X1 = | E9: =_xlfn.VAR.S(Données!C2:C1968) -> 68.469907 | G9: Variance X2 = | H9: =_xlfn.VAR.S(Données!D2:D1968) -> 0.063515452 | J9: Variance X3 = | K9: =_xlfn.VAR.S(Données!U2:U1968) -> 0.24385952 | M9: Variance X4 = | N9: =_xlfn.VAR.S(Données!V2:V1968) -> 0.35866104 | P9: Variance X5= | Q9: =_xlfn.VAR.S(Données!G2:G1968) -> 0.22438702 | S9: Variance X6= | T9: =_xlfn.VAR.S(Données!H2:H1968) -> 0.9452068 | V9: Variance X7= | W9: =_xlfn.VAR.S(Données!K2:K1968) -> 0.15152509
A10: Variance= | B10: =_xlfn.VAR.S(Données!A2:A1968) -> 6.5385142e+09
A11: Écart types= | B11: =_xlfn.STDEV.S(Données!A2:A1968) -> 80861.08
C18: X′X | L18: (X′X)^-1
C19: {=MMULT(TRANSPOSE(Données!R3:Y1969),Données!R3:Y1969)} -> 1967 | D19: 63713.59 | E19: 134 | F19: 23711.565 | G19: 16400.936 | H19: 1299 | I19: 396 | J19: 610 | L19: {=MINVERSE(_xlfn.ANCHORARRAY(C19))} -> 0.32256901 | M19: -0.00026879269 | N19: -0.0002400938 | O19: -0.025793485 | P19: -0.00066654779 | Q19: 0.0041347186 | R19: -0.00081853786 | S19: 0.0018913511 | U19: X'Y
C20: 63713.59 | D20: 2198374.7 | E20: 4673.9 | F20: 767983.59 | G20: 529006.79 | H20: 41845.8 | I20: 11385.5 | J20: 20028.19 | L20: -0.00026879269 | M20: 8.2577143e-06 | N20: -2.1582015e-05 | O20: -2.8365408e-05 | P20: 4.0970026e-05 | Q20: 7.3848107e-06 | R20: 6.9193207e-06 | S20: -1.018504e-05 | U20: {=MMULT(TRANSPOSE(Données!R3:Y1969),Données!Q3:Q1969)} -> 282106000
C21: 134 | D21: 4673.9 | E21: 134 | F21: 1614.1553 | G21: 1118.4892 | H21: 88 | I21: 24 | J21: 53 | L21: -0.0002400938 | M21: -2.1582015e-05 | N21: 0.008086039 | O21: 0.00012044305 | P21: -0.00011914362 | Q21: -1.4592472e-05 | R21: 7.7205832e-07 | S21: -0.00019569437 | U21: 9.2370848e+09
C22: 23711.565 | D22: 767983.59 | E22: 1614.1553 | F22: 286314.64 | G22: 198050.37 | H22: 15758.676 | I22: 4732.7427 | J22: 7390.8925 | L22: -0.025793485 | M22: -2.8365408e-05 | N22: 0.00012044305 | O22: 0.0034395758 | P22: -0.0017225082 | Q22: -0.00061099151 | R22: 5.0746085e-06 | S22: 1.9011378e-05 | U22: 20236000
C23: 16400.936 | D23: 529006.79 | E23: 1118.4892 | F23: 198050.37 | G23: 137456.52 | H23: 10877.266 | I23: 3268.9772 | J23: 5160.4601 | L23: -0.00066654779 | M23: 4.0970026e-05 | N23: -0.00011914362 | O23: -0.0017225082 | P23: 0.0024088148 | Q23: 0.00016782222 | R23: 4.8062056e-05 | S23: -0.00030125923 | U23: 3.4625697e+09
C24: 1299 | D24: 41845.8 | E24: 88 | F24: 15758.676 | G24: 10877.266 | H24: 1299 | I24: 207 | J24: 408 | L24: 0.0041347186 | M24: 7.3848107e-06 | N24: -1.4592472e-05 | O24: -0.00061099151 | P24: 0.00016782222 | Q24: 0.0023994528 | R24: 6.596839e-05 | S24: -1.5472344e-05 | U24: 2.4071961e+09
C25: 396 | D25: 11385.5 | E25: 24 | F25: 4732.7427 | G25: 3268.9772 | H25: 207 | I25: 1938 | J25: 165 | L25: -0.00081853786 | M25: 6.9193207e-06 | N25: 7.7205832e-07 | O25: 5.0746085e-06 | P25: 4.8062056e-05 | Q25: 6.596839e-05 | R25: 0.00054796894 | S25: -6.9135213e-05 | U25: 200067000
C26: 610 | D26: 20028.19 | E26: 53 | F26: 7390.8925 | G26: 5160.4601 | H26: 408 | I26: 165 | J26: 610 | L26: 0.0018913511 | M26: -1.018504e-05 | N26: -0.00019569437 | O26: 1.9011378e-05 | P26: -0.00030125923 | Q26: -1.5472344e-05 | R26: -6.9135213e-05 | S26: 0.0024466898 | U26: 49730000
U27: 99915000
C29: (X′X)^-1 * (X′Y) | E29: β
C30: {=MMULT(_xlfn.ANCHORARRAY(L19),_xlfn.ANCHORARRAY(U20))} -> -1429830 | E30: β0= | F30: =C30 -> -1429830
C31: 1222.041 | E31: β1= | F31: =C31 -> 1222.041
C32: 4348.812 | E32: β2= | F32: =C32 -> 4348.812
C33: 107195.57 | E33: β3= | F33: =C33 -> 107195.57
C34: 28045.793 | E34: β4= | F34: =C34 -> 28045.793
C35: 4514.0309 | E35: β5= | F35: =C35 -> 4514.0309
C36: -177.53907 | E36: β6= | F36: =C36 -> -177.53907
C37: 14086.931 | E37: β7= | F37: =C37 -> 14086.931
C44: SCT = | D44: =DEVSQ(Données!Q3:Q1969) -> 1.2854719e+13 | F44: R² = | G44: =1-(D46/D44) -> 0.66423949 | I44: ddl SCE = | J44: =6 -> 6
C45: SCE= | D45: =DEVSQ(Données!Z3:Z1969) -> 8.538612e+12 | I45: ddl SCR = | J45: =1960 -> 1960
C46: SCR= | D46: =SUMSQ(Données!AA3:AA1969) -> 4.316107e+12
C49: F observé = | D49: =(D45/B4)/(D46/(B5-B4-1)) -> 553.64512 | F49: p-valeur = | G49: =_xlfn.F.DIST.RT(D49,J44,J45) -> 0
C50: F théorique = | D50: =_xlfn.F.INV.RT(0.05,J44,J45) -> 2.1032022
F51: t théorique = | G51: =_xlfn.T.INV.2T(0.05,J45) -> 1.9611751
E57: =D46/J45 -> 2.2020954e+09
G58: {=E57*_xlfn.ANCHORARRAY(L19)} -> 7.1032773e+08 | H58: -591907.15 | I58: -528709.45 | J58: -56799715 | K58: -1467801.8 | L58: 9105044.8 | M58: -1802498.4 | N58: 4164935.5
G59: -591907.15 | H59: 18184.275 | I59: -47525.655 | J59: -62463.334 | K59: 90219.905 | L59: 16262.058 | M59: 15237.004 | N59: -22428.429
G60: -528709.45 | H60: -47525.655 | I60: 17806229 | J60: 265227.08 | K60: -262365.61 | L60: -32134.015 | M60: 1700.1461 | N60: -430937.68
G61: -56799715 | H61: -62463.334 | I61: 265227.08 | J61: 7574274.1 | K61: -3793127.4 | L61: -1345461.6 | M61: 11174.772 | N61: 41864.868
G62: -1467801.8 | H62: 90219.905 | I62: -262365.61 | J62: -3793127.4 | K62: 5304440 | L62: 369560.53 | M62: 105837.23 | N62: -663401.57
G63: 9105044.8 | H63: 16262.058 | I63: -32134.015 | J63: -1345461.6 | K63: 369560.53 | L63: 5283823.9 | M63: 145268.69 | N63: -34071.576
...

Sheet Description
A1: Variables | B1: Description
A2: PRET | B2: montant du prêt immobilier
A3: TX_EFF | B3: taux d'effort logement
A4: TX_ENDET | B4: taux d'endettement
A5: ANTEC | B5: 1 si antécédent dans le dossier de crédit (par exemple un défaut de paiement), 0 sinon
A6: TAUX | B6: 1 si taux fixe, 0 si taux variable
A7: PRIX | B7: prix d'achat du bien
A8: SEXE | B8: 1 si homme, 0 si femme
A9: MARIAGE | B9: 1 si marié, 0 sinon
A10: EMP | B10: ancienneté dans l'emploi actuel (en année)
A11: REVENU | B11: niveau de revenu mensuel (demandeur et codemandeur)
